Workbook

Sheet Summary
A1: SEO Audit: salesroads.com
A3: Audit date | B3: 2026-10-01
A4: Site | B4: https://salesroads.com/
A5: Overall health | B5: Needs Work
A6: Method | B6: Live crawl of all 390 sitemap URLs (raw HTML: titles, metas, headings, canonicals, robots, JSON-LD, links), robots.txt, 5 sub-sitemaps, cached vs uncached TTFB, plus SERP checks for core keywords, plus client-provided Semrush exports (Domain Overview, Organic Pages, Position Changes; Oct 1, 2026). Stack: WordPress + Elementor Pro + Rank Math on WP Engine / Cloudflare.
A8: Findings by priority
A9: Priority | B9: Total | C9: Done | D9: Open | E9: % Done
A10: Critical | B10: =COUNTIF('Action Tracker'!$C$5:$C$36,A10) -> 10 | C10: =COUNTIFS('Action Tracker'!$C$5:$C$36,A10,'Action Tracker'!$L$5:$L$36,"Done") -> 0 | D10: =B10-C10 -> 10 | E10: =IF(B10=0,0,C10/B10) -> 0
A11: Important | B11: =COUNTIF('Action Tracker'!$C$5:$C$36,A11) -> 16 | C11: =COUNTIFS('Action Tracker'!$C$5:$C$36,A11,'Action Tracker'!$L$5:$L$36,"Done") -> 0 | D11: =B11-C11 -> 16 | E11: =IF(B11=0,0,C11/B11) -> 0
A12: Nice-to-have | B12: =COUNTIF('Action Tracker'!$C$5:$C$36,A12) -> 6 | C12: =COUNTIFS('Action Tracker'!$C$5:$C$36,A12,'Action Tracker'!$L$5:$L$36,"Done") -> 0 | D12: =B12-C12 -> 6 | E12: =IF(B12=0,0,C12/B12) -> 0
A13: Total | B13: =SUM(B10:B12) -> 32 | C13: =SUM(C10:C12) -> 0 | D13: =SUM(D10:D12) -> 32 | E13: =IF(B13=0,0,C13/B13) -> 0
A15: Top critical issues
A16: C-01 | B16: 74-char site name appended to 153 page titles
A17: C-02 | B17: Junk WP username 'jjUplds9j0das0' published as Article author; users REST API open
A18: C-03 | B18: Thank-you, opt-in, PPC and duplicate pages are indexable and in the sitemap
A19: C-04 | B19: Blog posts cannibalize service pages for money keywords
A20: C-05 | B20: Slow uncached server response (TTFB)
A21: C-06 | B21: Generic or internal titles on key pages
A22: C-07 | B22: 43 pages have no meta description
A23: C-08 | B23: Missing H1 on key pages
A24: C-09 | B24: www.salesroads.com ranks as a separate homepage (Semrush)
A25: C-10 | B25: Temporary 307 redirect chains into top service pages
A27: What's working
B28: Public pricing on /pricing/ (rare among competitors) – a real asset for 'cost' queries.
B29: 33 case studies with named clients (Shell, Paylocity, Parker Hannifin, Clutch, Crewhu) and Challenge > Solution > Results structure.
B30: Original formats: Sell Like a Leader podcast (42 episodes), Sales Feud, SDR hiring white paper, monthly newsletter.
B31: Homepage ranks on page 1 for 'sales outsourcing company' (point-in-time sample).
B32: /lead-generation-services/ is a strong commercial page: 21% of organic traffic, ranks for 'lead generation services' (6.6K/mo) and 'lead generation companies' (4.4K/mo) (Semrush).
B33: HTTPS, self-referencing canonicals on all 390 URLs, correct 404s, OG/Twitter cards, Rank Math sitemaps incl. video sitemap.
A35: Tabs
A36: Action Tracker | B36: All findings with priority, recommendation, owner and status
A37: Quick Wins | B37: Top 10 actions to do first
A38: Title & Meta Rewrites | B38: Copy-paste titles/metas with length checks
A39: Content Plan | B39: New and rebuilt pages, with target queries and briefs
A40: Blog Cleanup | B40: Merge / refresh / prune decisions for existing posts
A41: Keyword Clusters | B41: Target clusters; fill in volumes from your SEO tool
A42: Semrush Data | B42: Traffic snapshot, top pages and new rankings from the Semrush exports
A43: External Checks | B43: Items to verify with GSC, PSI, Ahrefs, Screaming Frog
A44: Sources | B44: Evidence URLs

Sheet Action Tracker
A1: SalesRoads.com SEO Audit – Action Tracker
A2: Yellow columns (Owner, Due Date, Status, Notes) are for your team to fill in. Status 'Done' greys out the row and updates the Summary tab. Row 5 shows an example owner.
A4: ID | B4: Category | C4: Priority | D4: Finding | E4: Affected URLs / Evidence | F4: Why it matters | G4: Recommendation | H4: Effort | I4: Impact | J4: Owner | K4: Due Date | L4: Status | M4: Notes
A5: C-01 | B5: On-Page | C5: Critical | D5: 74-char site name appended to 153 page titles | E5: '- Sales Outsourcing Company | Outsourced Sales Team Services - SalesRoads' on /inbound-appointment-setting/ (101 chars), /logistics-supply-chain-industry/ (107), /manufacturing-industry-landing-page/ (109), /outbound-email-services/ (97)… | F5: Titles truncate at ~60 chars; keyword stuffed into 150+ titles dilutes relevance and competes with the homepage; leaks 'Industry Page' / 'Landing Page' names. | G5: Settings > General > Site Title (or Rank Math > Global Meta > Website Name) = 'SalesRoads'. Keep format %title% %sep% %sitename% with '|'. Then apply the 'Title & Meta Rewrites' tab. | H5: Low | I5: High | J5: SEO lead | L5: Not started | M5: Example row - replace with your owner
A6: C-02 | B6: Technical | C6: Critical | D6: Junk WP username 'jjUplds9j0das0' published as Article author; users REST API open | E6: Article + Person schema on homepage and 15 other pages; /wp-json/wp/v2/users returns 200 | F6: Negative E-E-A-T signal (homepage is not an Article) and exposes half of an admin login; user enumeration is trivial. | G6: Rank Math > Titles & Meta > Pages > Schema Type = None/WebPage. Set the user's public display name. Block /wp-json/wp/v2/users for anonymous requests; consider renaming the account. | H6: Low | I6: High | L6: Not started
A7: C-03 | B7: Technical | C7: Critical | D7: Thank-you, opt-in, PPC and duplicate pages are indexable and in the sitemap | E7: /request-received/, /meet-the-team/, /communication-opt-in-settings/, /vsa/ (16 of 20 headings = homepage), /appointment-setting-landing-page/, /lead-generation-landing-page/, /sales-outsourcing-landing-page/, /manufacturing-industry-landing-page/, /healthcare-industry-landing-page/ | F7: PPC duplicates compete with the real service pages; thank-you pages in search pollute conversion tracking. | G7: Add noindex and remove from the sitemap (Rank Math > Advanced on each page). Optionally 301 /vsa/ to / with a banner. | H7: Low | I7: High | L7: Not started
A8: C-04 | B8: Content | C8: Critical | D8: Blog posts cannibalize service pages for money keywords | E8: 40 URLs target 'appointment setting', 55 'lead generation', 43 'outsourcing'. /outsourcing/lead-generation-services/ shares the slug of /lead-generation-services/. Semrush: 'top outsourced sdr providers' ranks with / (#23) AND /outsourced-sdr-services/ (#61); 'appointment setting solutions' ranks with a blog post. See 'Blog Cleanup'. | F8: Google alternates between URLs; service pages absent from top 9 for 'B2B appointment setting services', 'outsourced SDR services', 'B2B cold calling services'. | G8: Confirm in GSC (query > Pages). Merge + 301 duplicates; re-angle remaining posts to informational intent; link to service page with exact-match anchors. | H8: Medium | I8: High | L8: Not started
A9: C-05 | B9: Technical | C9: Critical | D9: Slow uncached server response (TTFB) | E9: Cache MISS TTFB 1.9-3.2s on every page tested; 6-9s observed during crawl (/compliance-services-industry-page/ 9.7s). HTML cache max-age=600. | F9: Googlebot mostly hits cold cache on 348 posts; slow TTFB lowers crawl rate and LCP. | G9: Enable Cloudflare APO / edge HTML caching with purge-on-publish; profile origin (Query Monitor / New Relic); remove 'Crawl-delay: 10' from robots.txt. | H9: Medium | I9: High | L9: Not started
A10: C-06 | B10: On-Page | C10: Critical | D10: Generic or internal titles on key pages | E10: Blog, About Us, Careers, Why Choose Us, Methodology, Client Success, Sales Executives, Request a Quote, 'Insurtech Industry Page' | F10: Highest-intent pages give Google little to rank and earn low CTR. | G10: Apply the 'Title & Meta Rewrites' tab. | H10: Low | I10: High | L10: Not started
A11: C-07 | B11: On-Page | C11: Critical | D11: 43 pages have no meta description | E11: 25 podcast episodes, 5 outsourcing, 5 leadership posts, 4 case studies (Clutch, Bold Penguin, Rudholm, ZoomIn), VSA announcement | F11: Google auto-generates snippets, often from boilerplate. | G11: Write 140-155 char descriptions; lead case studies with the result metric. | H11: Medium | I11: Medium | L11: Not started
A12: C-08 | B12: On-Page | C12: Critical | D12: Missing H1 on key pages | E12: /blog/, /request-a-quote/, /all-industry-pages/, /communication-opt-in-settings/ | F12: Weak topical signal on hub and conversion pages. | G12: Add one descriptive H1 to each (e.g. 'B2B Sales & Outbound Prospecting Blog'). | H12: Low | I12: Medium | L12: Not started
A13: C-09 | B13: Technical | C13: Critical | D13: www.salesroads.com ranks as a separate homepage (Semrush) | E13: Semrush: https://www.salesroads.com/ = 12.0% of organic traffic, 34 keywords, 59 referring domains / 125 backlinks. Audit proxy blocked www so redirect unverified. | F13: Homepage signals may be split across two hosts. | G13: curl -sI https://www.salesroads.com/ and http://www… must return ONE 301 to https://salesroads.com/ (path preserved). Set in WP Engine Domains or Cloudflare redirect rule; check Google-selected canonical in GSC URL Inspection. | H13: Low | I13: High | L13: Not started
A14: C-10 | B14: Technical | C14: Critical | D14: Temporary 307 redirect chains into top service pages | E14: /leadgeneration 301>307>301; /lead-generation 307>301; /appointment-setting 307>301; /contact 301>301; /about and /case-studies 404 | F14: /lead-generation-services/ earns 21% of organic traffic; 307s don't reliably pass equity/canonical signals. | G14: Replace with single 301s to final trailing-slash URLs (WP Engine redirect rules or Rank Math Redirections); add 301 /about > /about-us/, /case-studies > /client-success/. | H14: Low | I14: High | L14: Not started
A15: I-01 | B15: Technical | C15: Important | D15: Self-serving / invalid review markup | E15: /reviews/ Product + AggregateRating (image is a .webm); /appointment-setting-services/ uses lowercase 'product' / 'aggregateRating' (invalid) | F15: Google does not show stars for self-reviews; marking a service as Product for stars risks a structured-data manual action. | G15: Remove Product/AggregateRating wrappers; keep attributed Review items only; fix or delete the lowercase block. | H15: Low | I15: Medium | L15: Not started
A16: I-02 | B16: Technical | C16: Important | D16: 340 of 347 BlogPostings lack datePublished/dateModified; no date shown on posts | E16: Rank Math BlogPosting schema; Elementor single-post template | F16: Freshness signal missing for 'how-to' and 'cost' queries and AI Overviews. | G16: Enable dates in Rank Math post schema; show 'Updated {date}' in the single-post template. | H16: Low | I16: Medium | L16: Not started
A17: I-03 | B17: Technical | C17: Important | D17: Organization schema is weak | E17: name = 'SalesRoads | America's Most-Trusted…', description 'All Things Sales Outsourcing', logo 'Untitled-Project-38.png', no sameAs | F17: Muddies the brand entity / Knowledge Panel. | G17: name 'SalesRoads', legalName 'Homebase-USA', foundingDate, sameAs (LinkedIn, Clutch, G2, YouTube, podcast); rename logo file. | H17: Low | I17: Medium | L17: Not started
... A36: N-06 | B36: Technical | C36: Nice-to-have | D36: No llms.txt | E36: /llms.txt returns 404; site has 'Ask ChatGPT / Claude / Perplexity' buttons | F36: Helps AI assistants find canonical service, pricing and case-study URLs. | G36: Add llms.txt (Rank Math can generate). | H36: Low | I36: Low | L36: Not started

Sheet Quick Wins
A1: Quick Wins – do these first
A3: # | B3: Action | C3: Tracker ID | D3: Est. effort | E3: Status (from tracker)
A4: 1 | B4: Set WordPress Site Title to 'SalesRoads' (removes 74-char suffix from 153 titles) | C4: C-01 | D4: 5 min | E4: =IFERROR(INDEX('Action Tracker'!$L$5:$L$36,MATCH(C4,'Action Tracker'!$A$5:$A$36,0)),"") -> Not started
A5: 2 | B5: Noindex + remove from sitemap: thank-you, opt-in, /vsa/ and 5 *-landing-page URLs | C5: C-03 | D5: 15 min | E5: =IFERROR(INDEX('Action Tracker'!$L$5:$L$36,MATCH(C5,'Action Tracker'!$A$5:$A$36,0)),"") -> Not started
A6: 3 | B6: Pages schema Article > WebPage; fix display name for jjUplds9j0das0; block users API | C6: C-02 | D6: 15 min | E6: =IFERROR(INDEX('Action Tracker'!$L$5:$L$36,MATCH(C6,'Action Tracker'!$A$5:$A$36,0)),"") -> Not started
A7: 4 | B7: Identify or remove the consortiumventure24.com script | C7: I-04 | D7: 15 min | E7: =IFERROR(INDEX('Action Tracker'!$L$5:$L$36,MATCH(C7,'Action Tracker'!$A$5:$A$36,0)),"") -> Not started
A8: 5 | B8: Paste titles + metas from 'Title & Meta Rewrites' for 25 commercial pages | C8: C-06 | D8: 1-2 hrs | E8: =IFERROR(INDEX('Action Tracker'!$L$5:$L$36,MATCH(C8,'Action Tracker'!$A$5:$A$36,0)),"") -> Not started
A9: 6 | B9: Fix Elementor heading templates: one H1, phone/CTA headings to <p> | C9: I-05 | D9: 1 hr | E9: =IFERROR(INDEX('Action Tracker'!$L$5:$L$36,MATCH(C9,'Action Tracker'!$A$5:$A$36,0)),"") -> Not started
A10: 7 | B10: Remove self-serving Product/AggregateRating schema | C10: I-01 | D10: 30 min | E10: =IFERROR(INDEX('Action Tracker'!$L$5:$L$36,MATCH(C10,'Action Tracker'!$A$5:$A$36,0)),"") -> Not started
A11: 8 | B11: Enable datePublished/dateModified + visible 'Updated' date on posts | C11: I-02 | D11: 30 min | E11: =IFERROR(INDEX('Action Tracker'!$L$5:$L$36,MATCH(C11,'Action Tracker'!$A$5:$A$36,0)),"") -> Not started
A12: 9 | B12: Rename/merge /outsourcing/lead-generation-services/ | C12: C-04 | D12: 30 min | E12: =IFERROR(INDEX('Action Tracker'!$L$5:$L$36,MATCH(C12,'Action Tracker'!$A$5:$A$36,0)),"") -> Not started
A13: 10 | B13: Cloudflare APO / edge HTML caching; remove Crawl-delay | C13: C-05 | D13: 1 hr | E13: =IFERROR(INDEX('Action Tracker'!$L$5:$L$36,MATCH(C13,'Action Tracker'!$A$5:$A$36,0)),"") -> Not started
A14: 11 | B14: Confirm www > apex is a single 301; check Google-selected canonical | C14: C-09 | D14: 15 min | E14: =IFERROR(INDEX('Action Tracker'!$L$5:$L$36,MATCH(C14,'Action Tracker'!$A$5:$A$36,0)),"") -> Not started
A15: 12 | B15: Replace 307 redirect chains (/leadgeneration, /lead-generation, /appointment-setting, /contact) with single 301s | C15: C-10 | D15: 15 min | E15: =IFERROR(INDEX('Action Tracker'!$L$5:$L$36,MATCH(C15,'Action Tracker'!$A$5:$A$36,0)),"") -> Not started
A16: 13 | B16: Add 'Hiring an SDR? Compare costs' CTA to job-description posts + service CTA on qualifying-leads-definition | C16: I-14 | D16: 1 hr | E16: =IFERROR(INDEX('Action Tracker'!$L$5:$L$36,MATCH(C16,'Action Tracker'!$A$5:$A$36,0)),"") -> Not started

Sheet Title & Meta Rewrites
A1: URL | B1: Current title (live HTML) | C1: Proposed title | D1: Proposed meta description | E1: Title length | F1: Meta length
A2: / | B2: Sales Outsourcing Company | Outsourced Sales Team Services - SalesRoads | C2: B2B Sales Outsourcing & Appointment Setting | SalesRoads | D2: US-based SDR teams that book qualified B2B meetings for you. Trusted by Shell, Paylocity & Clutch. Transparent pricing, cancel anytime. Get a quote. | E2: =LEN(C2) -> 56 | F2: =LEN(D2) -> 148
A3: /appointment-setting-services/ | B3: B2B Appointment Setting Services | SalesRoads | C3: B2B Appointment Setting Services | SalesRoads | D3: Onshore SDRs who book qualified meetings with decision-makers. 937 appointments for AchieveIt. See pricing and case studies, then request a quote. | E3: =LEN(C3) -> 45 | F3: =LEN(D3) -> 146
A4: /outsourced-sdr-services/ | B4: Outsourced SDR Services | SDR Outsourcing Company - SalesRoads | C4: Outsourced SDR Services: Dedicated US Reps | SalesRoads | D4: Get a fully managed outbound SDR team (reps, coaching, data ops and training) for less than the cost of hiring in-house. See pricing. | E4: =LEN(C4) -> 55 | F4: =LEN(D4) -> 133
A5: /outbound-calling-services/ | B5: B2B Cold Calling Services | Cold Calling Outsourcing - SalesRoads | C5: B2B Cold Calling Services by US-Based SDRs | SalesRoads | D5: Experienced onshore callers who reach decision-makers, qualify interest and book meetings with B2B decision-makers. Get a quote. | E5: =LEN(C5) -> 55 | F5: =LEN(D5) -> 128
A6: /lead-generation-services/ | B6: Outsourced Lead Generation Services: B2B Lead Generation Company | C6: B2B Lead Generation Services | SalesRoads | D6: Researched, phone-verified B2B leads and market-research lead generation that fill your pipeline with real buyers. See case studies and pricing. | E6: =LEN(C6) -> 41 | F6: =LEN(D6) -> 144
A7: /pricing/ | B7: Pricing - Sales Outsourcing Company | Outsourced Sales Team Services - SalesRoads | C7: SalesRoads Pricing: Outsourced SDR & Appointment Setting | D7: See exactly what an outsourced SDR program costs and how it compares with building in-house. Plans, what's included and FAQs. | E7: =LEN(C7) -> 56 | F7: =LEN(D7) -> 125
A8: /blog/ | B8: Blog | C8: B2B Sales Blog: Cold Calling, SDR & Lead Gen | SalesRoads | D8: Practical guides on cold calling, outbound email, SDR management and lead generation from the team that has booked thousands of B2B meetings. | E8: =LEN(C8) -> 57 | F8: =LEN(D8) -> 141
A9: /about-us/ | B9: About Us | C9: About SalesRoads: US-Based Sales Development Since 2007 | D9: Meet the onshore sales development team behind 33+ published client wins, 3× Inc. 5000 and a 4.9 Clutch rating. Our story, mission and people. | E9: =LEN(C9) -> 55 | F9: =LEN(D9) -> 142
A10: /why-us/ | B10: Why Choose Us | C10: Why SalesRoads: Onshore SDRs & Proven Results | D10: Senior US-based reps, transparent reporting, no long-term contracts. See how SalesRoads differs from other appointment setting agencies. | E10: =LEN(C10) -> 45 | F10: =LEN(D10) -> 136
A11: /reviews/ | B11: Client Reviews | C11: SalesRoads Reviews: 4.9★ Client Ratings & Testimonials | D11: Read verified client reviews of SalesRoads' appointment setting and SDR services from Clutch and G2, plus answers to common questions. | E11: =LEN(C11) -> 54 | F11: =LEN(D11) -> 134
A12: /inbound-appointment-setting/ | B12: Inbound Appointment Setting - Sales Outsourcing Company | Outsourced Sales Team Services - SalesRoads | C12: Inbound Appointment Setting & Lead Response | SalesRoads | D12: Stop letting ready buyers slip through the cracks. Our SDRs follow up on inbound leads and turn them into booked meetings. | E12: =LEN(C12) -> 56 | F12: =LEN(D12) -> 122
A13: /outbound-email-services/ | B13: Outbound Email Services - Sales Outsourcing Company | Outsourced Sales Team Services - SalesRoads | C13: Outbound Email Services: B2B Cold Email | SalesRoads | D13: Personalized B2B cold email campaigns written and run by SDRs, with deliverability managed and replies converted into meetings. | E13: =LEN(C13) -> 52 | F13: =LEN(D13) -> 127
... A26: /careers/ | B26: Careers | C26: Sales Development Careers at SalesRoads | D26: Join a sales development team built for growth: training, coaching and a culture that feels like home. See open SDR roles. | E26: =LEN(C26) -> 39 | F26: =LEN(D26) -> 122
A28: Lengths over 60 (title) / 160 (meta) turn yellow. Check every proof point (client names, numbers, 'cancel anytime', Clutch rating) against current facts before publishing.

Sheet Content Plan
A1: Group | B1: Type | C1: Proposed URL | D1: Target queries | E1: Intent | F1: Priority | G1: Brief / key elements | H1: Owner | I1: Status
A2: A | B2: Reviews | C2: /salesroads-reviews/ (or expand /reviews/) | D2: salesroads reviews; salesroads alternatives; salesroads pricing | E2: Commercial | F2: Critical | G2: Clutch/G2 ratings with links, current pricing, who SalesRoads is NOT a fit for, comparison on onshore reps, terms, reporting. WebPage + FAQPage schema. | I2: Not started
A3: A | B3: Comparison | C3: /compare/salesroads-vs-superhuman-prospecting | D3: superhuman prospecting alternative; vs salesroads | E3: Transactional | F3: Important | G3: Semrush #2 organic competitor (20% overlap). Feature/pricing/contract table, onshore vs offshore, minimum term, best-for. | I3: Not started
A4: A | B4: Comparison | C4: /compare/salesroads-vs-sales-focus | D4: sales focus inc alternative; vs salesroads | E4: Transactional | F4: Important | G4: Semrush #3 organic competitor (19%). Same template. | I4: Not started
A5: A | B5: Comparison | C5: /compare/salesroads-vs-salesbread | D5: salesbread alternative; vs salesroads | E5: Transactional | F5: Important | G5: Semrush #5 (15%); SalesBread publishes a SalesRoads review page. Same template. | I5: Not started
A6: A | B6: Comparison | C6: /compare/salesroads-vs-memoryblue | D6: memoryblue vs salesroads; memoryblue alternative | E6: Transactional | F6: Nice-to-have | G6: G2 hosts this comparison. Same template. | I6: Not started
A7: A | B7: Comparison | C7: /compare/salesroads-vs-saleshive | D7: saleshive vs salesroads; saleshive alternative | E7: Transactional | F7: Nice-to-have | G7: Same template. | I7: Not started
A8: A | B8: Comparison | C8: /compare/salesroads-vs-belkins | D8: belkins vs salesroads; belkins alternative | E8: Transactional | F8: Critical | G8: Semrush #1 organic competitor (27% overlap). Same template. | I8: Not started
A9: A | B9: Comparison | C9: /compare/salesroads-vs-callbox | D9: callbox vs salesroads; callbox alternative | E9: Transactional | F9: Important | G9: Same template. | I9: Not started
A10: A | B10: Comparison | C10: /compare/salesroads-vs-martal | D10: martal vs salesroads; martal group alternative | E10: Transactional | F10: Nice-to-have | G10: Same template. | I10: Not started
A11: B | B11: Pillar rebuild | C11: /appointment-setting-services/ | D11: b2b appointment setting services; outsourced appointment setting; appointment setting company | E11: Commercial | F11: Critical | G11: Merge /outsourcing/outsourced-appointment-setting/ + /outsourcing/everything-to-know-about-b2b-appointment-setting/ (301). Add weeks 1-6 timeline, pricing summary, 3 case-study results, industries grid, FAQs. 2,000+ words unique. | I11: Not started
A12: B | B12: Pillar rebuild | C12: /outsourced-sdr-services/ | D12: outsourced sdr services; sdr as a service; sdr outsourcing | E12: Commercial | F12: Critical | G12: Merge /outsourcing/sdr-outsourcing/ + /outsourcing/sales-development-services/. Add in-house vs outsourced SDR cost calculator (data from /outsourcing/in-house-sdr-costs/). | I12: Not started
A13: B | B13: Pillar rebuild | C13: /outbound-calling-services/ | D13: b2b cold calling services; cold calling outsourcing | E13: Commercial | F13: Important | G13: One H1; process, call-quality controls, case results, FAQs. | I13: Not started
... A21: D | B21: Podcast | C21: /podcast/* (42 episodes) | D21: <guest> podcast; sales leadership podcast | E21: Informational | F21: Nice-to-have | G21: 300-600 word summary, takeaways, transcript, meta description per episode. | I21: Not started
A23: Groups: A = brand & comparison, B = service pillars & cost guide, C = industries, D = hubs & podcast.

Sheet Blog Cleanup
A1: URL | B1: Action | C1: Notes | D1: Done?
A2: /outsourcing/lead-generation-services/ | B2: Merge | C2: 301 into /lead-generation-services/ (same slug as the service page) or rename to /outsourcing/outbound-lead-generation-guide/
A3: /outsourcing/outsourced-lead-generation/ | B3: Re-angle | C3: Informational ('guide to outsourcing lead gen'); link to /lead-generation-services/
A4: /outsourcing/outsource-lead-generation/ | B4: Merge | C4: 301 into /outsourcing/outsourced-lead-generation/
A5: /outsourcing/outsourced-appointment-setting/ | B5: Keep + re-angle | C5: Semrush: 2.7% of traffic, 27 kw. Re-angle to informational (what it is, pros/cons) and link to /appointment-setting-services/. Merge only if GSC shows both URLs swapping on the same queries.
A6: /outsourcing/everything-to-know-about-b2b-appointment-setting/ | B6: Merge | C6: 301 into /appointment-setting-services/
A7: /outsourcing/call-center-appointment-setting/ | B7: Re-angle | C7: Keep as call-center angle; link to service page
A8: /outsourcing/sdr-outsourcing/ | B8: Merge | C8: 301 into /outsourced-sdr-services/
A9: /outsourcing/sales-development-services/ | B9: Merge | C9: 301 into /outsourced-sdr-services/
A10: /outsourcing/sales-outsourcing-pricing/ | B10: Keep (survivor) | C10: Semrush: 31 kw. Becomes the cost guide; keep URL
A11: /outsourcing/appointment-setting-pricing-models/ | B11: Merge | C11: 301 into /outsourcing/sales-outsourcing-pricing/
A12: /tactics/lead-generation-pricing/ | B12: Merge | C12: 301 into /outsourcing/sales-outsourcing-pricing/
A13: /outsourcing/how-much-does-salesroads-sales-outsourcing-actually-cost/ | B13: Keep + link | C13: Brand pricing explainer; add meta description; link to /pricing/
... A45: /leadership/the-3-ai-lessons-every-sales-leader-needs-to-learn-right-now/ | B45: Publish or remove | C45: Noindex but internally linked
A47: Before merging, check GSC clicks and Ahrefs backlinks for each URL and keep the stronger one; always 301 the merged URL.

Sheet Keyword Clusters
A1: Cluster | B1: Example queries | C1: Intent | D1: Target page | E1: Monthly volume | F1: Keyword difficulty | G1: Current rank
A2: Appointment setting | B2: b2b appointment setting services; outsourced appointment setting; appointment setting company | C2: Commercial | D2: /appointment-setting-services/ | G2: Not in top 9 (sample)
A3: SDR outsourcing | B3: outsourced sdr services; sdr as a service; top outsourced sdr providers for b2b sales | C3: Commercial | D3: /outsourced-sdr-services/ | G3: Not in top 9 (sample); 'top outsourced sdr providers' #23 (home) and #61 (service page)
A4: Cold calling | B4: b2b cold calling services; cold calling outsourcing; cold calling company | C4: Commercial | D4: /outbound-calling-services/ | G4: Not in top 9 (sample)
A5: Lead generation | B5: lead generation services (6,600/mo); lead generation companies (4,400/mo); outsourced lead generation | C5: Commercial | D5: /lead-generation-services/ | G5: Ranks with SERP feature (Semrush); 21% of traffic
A6: Sales outsourcing | B6: sales outsourcing company; outsourced sales team; b2b telesales companies | C6: Commercial | D6: / | G6: Page 1 (sample); 'b2b telesales companies' #49
A7: Pricing / cost | B7: appointment setting cost; cost per appointment; sales outsourcing cost; sdr cost | C7: Commercial / Info | D7: /pricing/ + cost guide | G7: Not in top 9 (sample)
A8: Brand / comparison | B8: salesroads reviews; salesroads alternatives; <competitor> vs salesroads | C8: Transactional | D8: Reviews page + /compare/* | G8: Third parties own SERP
A9: Industry | B9: saas / healthcare / fintech / manufacturing / government appointment setting | C9: Commercial | D9: Industry pages
A10: Cold calling how-to | B10: cold calling scripts; cold call opening lines; cold calling objections | C10: Informational | D10: /tactics/cold-calling-scripts/ etc.
A11: SDR management | B11: sdr metrics; sdr onboarding; sdr vs bdr; sdr ae (70/mo); sdr salary | C11: Informational | D11: /leadership/* posts | G11: 'sdr ae' #23
A12: Hiring / job descriptions | B12: appointment setter job description; lead generation job description; manager in business development (3,600/mo) | C12: Info (hiring managers) | D12: /leadership/*-job-description/ | G12: 'manager in business development' #13; 3 posts = 3.6% of traffic
A13: Definitions | B13: define qualify (2,900/mo); sales executive meaning | C13: Informational | D13: /tactics/qualifying-leads-definition/, /leadership/sales-executive-meaning/ | G13: 'define qualify' #2
A15: Volumes and difficulty: fill from Semrush / Ahrefs / Google Keyword Planner. 'Current rank' notes come from a single SERP sample on 2026-10-01; replace with tracked positions.

Sheet Semrush Data
A1: Semrush Data – salesroads.com (US, desktop, exports dated 2026-10-01)
A2: Source: client-provided Semrush Domain Overview, Organic Research: Pages and Organic Position Changes exports. Peak traffic is read from the trend chart (approximate).
A4: Metric | B4: Value | G4: Note
A5: Organic traffic / month | B5: 3100 | G5: +6% MoM; ~40% below 2025 peak (~5.5K)
A6: 2025 peak traffic (approx.) | B6: 5500 | G6: Read from Semrush trend chart
A7: Ranking keywords | B7: 4083 | G7: 72.7% informational, 21.9% commercial, 3.5% transactional
A8: Keywords in positions 1-3 | B8: 85
A9: Keywords in positions 4-10 | B9: 285
A10: Keywords in positions 11-20 | B10: 453 | G10: Striking distance – refresh these first
A11: Backlinks | B11: 12000 | G11: 60% follow
A12: Referring domains | B12: 2000 | G12: Top referrers are directories/list sites
A13: Branded traffic share | B13: 0.229 | G13: 45 branded keywords, 718 visits
A14: Paid keywords | B14: 0 | G14: No Google Ads
A15: Change from peak | B15: =IF(B6=0,0,B5/B6-1) -> -0.4364 | G15: Formula: current / peak - 1
A17: Top pages by share of organic traffic
A18: URL | B18: Traffic % | C18: Keywords | G18: Note
A19: / | B19: 0.2557 | C19: 386
A20: /lead-generation-services/ | B20: 0.2133 | C20: 165 | G20: Protect – see C-10 redirect chains
A21: https://www.salesroads.com/ | B21: 0.1195 | C21: 34 | G21: Separate www homepage – see C-09
A22: /appointment-setting-services/ | B22: 0.1001 | C22: 152
A23: /tactics/qualifying-leads-definition/ | B23: 0.0599 | C23: 56 | G23: #2 'define qualify' – add service CTA (I-14)
A24: /leadership/sales-executive-meaning/ | B24: 0.036 | C24: 62
A25: /outsourcing/outsourced-appointment-setting/ | B25: 0.0267 | C25: 27 | G25: Ranks on its own – re-angle, don't blindly merge
A26: /tactics/generating-b2b-leads/ | B26: 0.02 | C26: 61 | G26: Survivor of lead-gen tips merge
A27: /outsourced-sdr-services/ | B27: 0.0184 | C27: 60
A28: /leadership/appointment-setting-job-description/ | B28: 0.0172 | C28: 59 | G28: Hiring-manager traffic – add CTA (I-14)
A29: /careers/ | B29: 0.0127 | C29: 7
A30: /tactics/targeted-lead-generation/ | B30: 0.0121 | C30: 17
A31: /leadership/lead-generation-job-description/ | B31: 0.0121 | C31: 37
A32: /tactics/financial-advisors-appointment-setting-services/ | B32: 0.0117 | C32: 13
A33: /leadership/business-development-and-sales-manager-job-description/ | B33: 0.0073 | C33: 56
A34: /tactics/value-proposition/ | B34: 0.0063 | C34: 6
A35: /tactics/saas-lead-generation-strategies/ | B35: 0.0063 | C35: 29
A36: /tactics/sales-competency-development/ | B36: 0.0041 | C36: 17
A37: /tactics/account-based-marketing-strategies/ | B37: 0.0038 | C37: 102
A38: /leadership/sales-development-representative/ | B38: 0.0035 | C38: 25
A39: Top 4 URLs combined | B39: =SUM(B19:B22) -> 0.6886
A41: New rankings on 2026-09-30 (Position Changes export)
A42: Keyword | B42: Position | C42: Volume | D42: KD | E42: Intent | F42: Traffic change | G42: URL
A43: manager in business development | B43: 13 | C43: 3600 | D43: 31 | E43: informational | F43: 18 | G43: /leadership/business-development-and-sales-manager-job-description/
...

Sheet External Checks
A1: Check | B1: Why not verified | C1: Tool | D1: Result / Notes
A2: Core Web Vitals (LCP, INP, CLS) field data | B2: Needs CrUX / real-user data | C2: PageSpeed Insights; GSC > Core Web Vitals
A3: Index coverage; excluded URLs | B3: Needs Search Console access | C3: GSC > Pages
A4: Cannibalization by query | B4: Needs Search Console access | C4: GSC > Performance > filter query > Pages tab
A5: Exact rankings and search volume | B5: SERP checks were a point-in-time sample | C5: Semrush / Ahrefs position tracking
A6: Backlinks per merge candidate | B6: Semrush export covers top 5 pages only | C6: Semrush Backlinks > Indexed Pages / Ahrefs / GSC > Links
A7: www > apex redirect (HIGH – Semrush shows www ranking, C-09) | B7: Audit proxy blocked www.salesroads.com | C7: curl -sI https://www.salesroads.com/; GSC URL Inspection
A8: What consortiumventure24.com/js/812387.js is | B8: Audit proxy blocked the domain | C8: Google Tag Assistant; ask marketing ops
A9: Rendered DOM / JS-dependent content | B9: Raw-HTML crawl only | C9: Screaming Frog (JS rendering); GSC URL Inspection

Sheet Sources
A1: Source | B1: URL
A2: SalesRoads homepage | B2: https://salesroads.com/
A3: robots.txt | B3: https://salesroads.com/robots.txt
A4: Sitemap index | B4: https://salesroads.com/sitemap_index.xml
A5: Pricing | B5: https://salesroads.com/pricing/
A6: Reviews | B6: https://salesroads.com/reviews/
A7: Appointment setting services | B7: https://salesroads.com/appointment-setting-services/
A8: VSA landing page | B8: https://salesroads.com/vsa/
A9: WP users endpoint | B9: https://salesroads.com/wp-json/wp/v2/users
A10: G2 – SalesRoads alternatives | B10: https://www.g2.com/products/salesroads/competitors/alternatives
A11: G2 – SalesRoads vs memoryBlue | B11: https://www.g2.com/compare/salesroads-vs-memoryblue
A12: Cleverly – SalesRoads review | B12: https://www.cleverly.co/blog/salesroads-reviews
... A26: Semrush exports (client-provided, 2026-10-01): Domain Overview, Organic Pages, Position Changes | B26: https://www.semrush.com/
